Epoch 1/10
Traceback (most recent call last):
  File "/Users/Aresh/Desktop/Projects/Image Classification with TensorFlow/image_classification.py", line 38, in <module>
    history = model.fit(
              ^^^^^^^^^^
  File "/Users/Aresh/Desktop/Projects/Image Classification with TensorFlow/.venv/lib/python3.12/site-packages/keras/src/utils/traceback_utils.py", line 122, in error_handler
    raise e.with_traceback(filtered_tb) from None
  File "/Users/Aresh/Desktop/Projects/Image Classification with TensorFlow/.venv/lib/python3.12/site-packages/keras/src/layers/input_spec.py", line 160, in assert_input_compatibility
    raise ValueError(
ValueError: Exception encountered when calling Sequential.call().

Layer "conv2d" expects 1 input(s), but it received 2 input tensors. Inputs received: [<tf.Tensor 'data:0' shape=(None, 28, 28, 1) dtype=uint8>, <tf.Tensor 'data_1:0' shape=(None,) dtype=int64>]

Arguments received by Sequential.call():
  • inputs={'image': 'tf.Tensor(shape=(None, 28, 28, 1), dtype=uint8)', 'label': 'tf.Tensor(shape=(None,), dtype=int64)'}
  • training=True
  • mask={'image': 'None', 'label': 'None'}